<?xml version="1.0" encoding="UTF-8"?>
<robot name="InspireHand_OY_Left">
  <joint name="hand1_joint_link_1_1" type="revolute">
    <origin xyz="0.022705 -0.019251 0.047312" rpy="-0.0083817 0.21825 -0.038695 "/>
    <parent link="hand1_link_base"/>
    <child link="hand1_link_1_1"/>
    <axis xyz="0. 0. 1."/>
    <limit lower="0." upper="1.5699999" effort="10." velocity="1.364"/>
  </joint>
  <joint name="hand1_joint_link_1_2" type="revolute">
    <origin xyz="0.00275 -0.015346 0.017066" rpy="0. 0. -0."/>
    <parent link="hand1_link_1_1"/>
    <child link="hand1_link_1_2"/>
    <axis xyz="1. 0. 0."/>
    <limit lower="0.04" upper="0.6416" effort="10." velocity="1.364"/>
  </joint>
  <joint name="hand1_joint_link_1_3" type="revolute">
    <origin xyz="0. 0. 0.046398" rpy="-0.19193 0. 0. "/>
    <parent link="hand1_link_1_2"/>
    <child link="hand1_link_1_3"/>
    <axis xyz="1. 0. 0."/>
    <limit lower="-0.5" upper="0.04" effort="10." velocity="1.364"/>
    <mimic joint="hand1_joint_link_1_2" multiplier="0.89761" offset="-0.535904255" />
  </joint>
  <joint name="hand1_joint_link_1_4" type="fixed">
    <origin xyz="0. -0.0046792 0.018289 " rpy="1.5707973 1.3788673 1.5707973"/>
    <parent link="hand1_link_1_3"/>
    <child link="hand1_link_1_4"/>
  </joint>
  <joint name="hand1_joint_link_2_1" type="revolute">
    <origin xyz="-0.0026645 -0.029097 0.1161 " rpy="-1.5647001 0.06952 -1.4833 "/>
    <parent link="hand1_link_base"/>
    <child link="hand1_link_2_1"/>
    <axis xyz="1. 0. 0."/>
    <limit lower="1.7499999" upper="3.1099998" effort="10." velocity="1.364"/>
  </joint>
  <joint name="hand1_joint_link_2_2" type="revolute">
    <origin xyz="0. 0.035919 -0.000219" rpy="-0. 0. -0."/>
    <parent link="hand1_link_2_1"/>
    <child link="hand1_link_2_2"/>
    <axis xyz="1. 0. 0."/>
    <limit lower="0.02845" upper="1.5699999" effort="10." velocity="1.364"/>
    <mimic joint="hand1_joint_link_2_1" multiplier="1.13349" offset="-1.954170452" />
  </joint>
  <joint name="hand1_joint_link_2_3" type="fixed">
    <origin xyz="0. -0.0002353 -0.04385 " rpy="-1.5707726 -0.0061038 -1.5707965"/>
    <parent link="hand1_link_2_2"/>
    <child link="hand1_link_2_3"/>
  </joint>
  <joint name="hand1_joint_link_3_1" type="revolute">
    <origin xyz="-0.0069662 -0.0090558 0.1191 " rpy="-1.5708 0.0000001 -1.5708 "/>
    <parent link="hand1_link_base"/>
    <child link="hand1_link_3_1"/>
    <axis xyz="1. 0. 0."/>
    <limit lower="1.7099999" upper="3.0699997" effort="10." velocity="1.364"/>
  </joint>
  <joint name="hand1_joint_link_3_2" type="revolute">
    <origin xyz="0.0000428 0.041009 0. " rpy="0. -0. 0.011929"/>
    <parent link="hand1_link_3_1"/>
    <child link="hand1_link_3_2"/>
    <axis xyz="1. 0. 0."/>
    <limit lower="0.0688" upper="1.5699999" effort="10." velocity="1.364"/>
    <mimic joint="hand1_joint_link_3_1" multiplier="1.10382" offset="-1.81781665" />
  </joint>
  <joint name="hand1_joint_link_3_3" type="fixed">
    <origin xyz="0.0000142 -0.0018023 -0.043814 " rpy="-1.5707964 -0.0000036 -1.5707878"/>
    <parent link="hand1_link_3_2"/>
    <child link="hand1_link_3_3"/>
  </joint>
  <joint name="hand1_joint_link_4_1" type="revolute">
    <origin xyz="-0.0062162 0.010944 0.1161 " rpy="-1.5708 -0.0698469 -1.5708 "/>
    <parent link="hand1_link_base"/>
    <child link="hand1_link_4_1"/>
    <axis xyz="1. 0. 0."/>
    <limit lower="1.7699998" upper="3.0799999" effort="10." velocity="1.364"/>
  </joint>
  <joint name="hand1_joint_link_4_2" type="revolute">
    <origin xyz="-0. 0.03592 0. " rpy="0. -0. 0.0000001"/>
    <parent link="hand1_link_4_1"/>
    <child link="hand1_link_4_2"/>
    <axis xyz="1. 0. 0."/>
    <limit lower="0.06" upper="1.5699999" effort="10." velocity="1.364"/>
    <mimic joint="hand1_joint_link_4_1" multiplier="1.15267" offset="-1.979224338" />
  </joint>
  <joint name="hand1_joint_link_4_3" type="fixed">
    <origin xyz="-0. -0.0022757 -0.043792 " rpy="-1.5707725 -0.0000036 -1.5707963"/>
    <parent link="hand1_link_4_2"/>
    <child link="hand1_link_4_3"/>
  </joint>
  <joint name="hand1_joint_link_5_1" type="revolute">
    <origin xyz="-0.0036637 0.030986 0.11208 " rpy="-1.5592998 -0.1312 -1.6588 "/>
    <parent link="hand1_link_base"/>
    <child link="hand1_link_5_1"/>
    <axis xyz="1. 0. 0."/>
    <limit lower="1.73" upper="3.0499999" effort="10." velocity="1.364"/>
  </joint>
  <joint name="hand1_joint_link_5_2" type="revolute">
    <origin xyz="-0. 0.031929 -0.0003684" rpy="0. -0. 0."/>
    <parent link="hand1_link_5_1"/>
    <child link="hand1_link_5_2"/>
    <axis xyz="1. 0. 0."/>
    <limit lower="0.09" upper="1.5699999" effort="10." velocity="1.364"/>
    <mimic joint="hand1_joint_link_5_1" multiplier="1.12121" offset="-1.848759431" />
  </joint>
  <joint name="hand1_joint_link_5_3" type="fixed">
    <origin xyz="0. -0.0012841 -0.031579 " rpy="-1.5707964 -0.0115037 -1.5707964"/>
    <parent link="hand1_link_5_2"/>
    <child link="hand1_link_5_3"/>
  </joint>
  <link name="hand1_link_1_1">
    <visual>
      <origin xyz="0. 0. 0." rpy="0. 0. 0."/>
      <geometry>
        <mesh filename="meshes/hand1_link_1_1_visuals.obj" scale="1. 1. 1."/>
      </geometry>
    </visual>
    <collision>
      <origin xyz="0. 0. 0." rpy="0. 0. 0."/>
      <geometry>
        <mesh filename="meshes/hand1_link_1_1_collisions.obj" scale="1. 1. 1."/>
      </geometry>
    </collision>
  </link>
  <link name="hand1_link_1_2">
    <inertial>
      <origin xyz="0. 0. 0." rpy="0. 0. 0."/>
      <mass value="0.022429"/>
      <inertia ixx="0." ixy="0." ixz="0." iyy="0." iyz="0." izz="0."/>
    </inertial>
    <visual>
      <origin xyz="0. 0. 0." rpy="0. 0. 0."/>
      <geometry>
        <mesh filename="meshes/hand1_link_1_2_visuals.obj" scale="1. 1. 1."/>
      </geometry>
    </visual>
    <collision>
      <origin xyz="0. 0. 0." rpy="0. 0. 0."/>
      <geometry>
        <mesh filename="meshes/hand1_link_1_2_collisions.obj" scale="1. 1. 1."/>
      </geometry>
    </collision>
  </link>
  <link name="hand1_link_1_3">
    <inertial>
      <origin xyz="0. 0. 0." rpy="0. 0. 0."/>
      <mass value="0.0022502"/>
      <inertia ixx="0." ixy="0." ixz="0." iyy="0." iyz="0." izz="0."/>
    </inertial>
    <visual>
      <origin xyz="0. 0. -0." rpy="-0.0000009 0.0000002 0. "/>
      <geometry>
        <mesh filename="meshes/hand1_link_1_3_visuals.obj" scale="1. 1. 1."/>
      </geometry>
    </visual>
    <collision>
      <origin xyz="0. 0. -0." rpy="-0.0000009 0.0000002 0. "/>
      <geometry>
        <mesh filename="meshes/hand1_link_1_3_collisions.obj" scale="1. 1. 1."/>
      </geometry>
    </collision>
  </link>
  <link name="hand1_link_1_4">
    <inertial>
      <origin xyz="0. 0. 0." rpy="0. 0. 0."/>
      <mass value="0.0000002"/>
      <inertia ixx="0." ixy="0." ixz="0." iyy="0." iyz="0." izz="0."/>
    </inertial>
    <visual>
      <origin xyz="-0. 0. 0." rpy="-3.0166261 -1.5707961 3.0166261"/>
      <geometry>
        <mesh filename="meshes/hand1_link_1_4_visuals.obj" scale="1. 1. 1."/>
      </geometry>
    </visual>
    <collision>
      <origin xyz="-0. 0. 0." rpy="-3.0166261 -1.5707961 3.0166261"/>
      <geometry>
        <mesh filename="meshes/hand1_link_1_4_collisions.obj" scale="1. 1. 1."/>
      </geometry>
    </collision>
  </link>
  <link name="hand1_link_2_1">
    <inertial>
      <origin xyz="0. 0. 0." rpy="0. 0. 0."/>
      <mass value="0.0059375"/>
      <inertia ixx="0." ixy="0." ixz="0." iyy="0." iyz="0." izz="0."/>
    </inertial>
    <visual>
      <origin xyz="0. 0. 0." rpy="0. 0. 0."/>
      <geometry>
        <mesh filename="meshes/hand1_link_2_1_visuals.obj" scale="1. 1. 1."/>
      </geometry>
    </visual>
    <collision>
      <origin xyz="0. 0. 0." rpy="0. 0. 0."/>
      <geometry>
        <mesh filename="meshes/hand1_link_2_1_collisions.obj" scale="1. 1. 1."/>
      </geometry>
    </collision>
  </link>
  <link name="hand1_link_2_2">
    <inertial>
      <origin xyz="0. 0. 0." rpy="0. 0. 0."/>
      <mass value="0.012005"/>
      <inertia ixx="0." ixy="0." ixz="0." iyy="0." iyz="0." izz="0."/>
    </inertial>
    <visual>
      <origin xyz="0. 0. 0." rpy="0. 0. 0."/>
      <geometry>
        <mesh filename="meshes/hand1_link_2_2_visuals.obj" scale="1. 1. 1."/>
      </geometry>
    </visual>
    <collision>
      <origin xyz="0. 0. 0." rpy="0. 0. 0."/>
      <geometry>
        <mesh filename="meshes/hand1_link_2_2_collisions.obj" scale="1. 1. 1."/>
      </geometry>
    </collision>
  </link>
  <link name="hand1_link_2_3">
    <inertial>
      <origin xyz="0. 0. 0." rpy="0. 0. 0."/>
      <mass value="0.0000002"/>
      <inertia ixx="0." ixy="0." ixz="0." iyy="0." iyz="0." izz="0."/>
    </inertial>
    <visual>
      <origin xyz="0. -0. 0." rpy="-1.5707963 -1.5707961 1.5707964"/>
      <geometry>
        <mesh filename="meshes/hand1_link_2_3_visuals.obj" scale="1. 1. 1."/>
      </geometry>
    </visual>
    <collision>
      <origin xyz="0. -0. 0." rpy="-1.5707963 -1.5707961 1.5707964"/>
      <geometry>
        <mesh filename="meshes/hand1_link_2_3_collisions.obj" scale="1. 1. 1."/>
      </geometry>
    </collision>
  </link>
  <link name="hand1_link_3_1">
    <inertial>
      <origin xyz="0. 0. 0." rpy="0. 0. 0."/>
      <mass value="0.0067572"/>
      <inertia ixx="0." ixy="0." ixz="0." iyy="0." iyz="0." izz="0."/>
    </inertial>
    <visual>
      <origin xyz="0. 0. 0." rpy="0. -0. -0."/>
      <geometry>
        <mesh filename="meshes/hand1_link_3_1_visuals.obj" scale="1. 1. 1."/>
      </geometry>
    </visual>
    <collision>
      <origin xyz="0. 0. 0." rpy="0. -0. -0."/>
      <geometry>
        <mesh filename="meshes/hand1_link_3_1_collisions.obj" scale="1. 1. 1."/>
      </geometry>
    </collision>
  </link>
  <link name="hand1_link_3_2">
    <inertial>
      <origin xyz="0. 0. 0." rpy="0. 0. 0."/>
      <mass value="0.012005"/>
      <inertia ixx="0." ixy="0." ixz="0." iyy="0." iyz="0." izz="0."/>
    </inertial>
    <visual>
      <origin xyz="-0. 0. -0." rpy="-0. -0. 0.0000086"/>
      <geometry>
        <mesh filename="meshes/hand1_link_3_2_visuals.obj" scale="1. 1. 1."/>
      </geometry>
    </visual>
    <collision>
      <origin xyz="-0. 0. -0." rpy="-0. -0. 0.0000086"/>
      <geometry>
        <mesh filename="meshes/hand1_link_3_2_collisions.obj" scale="1. 1. 1."/>
      </geometry>
    </collision>
  </link>
  <link name="hand1_link_3_3">
    <inertial>
      <origin xyz="0. 0. 0." rpy="0. 0. 0."/>
      <mass value="0.0000002"/>
      <inertia ixx="0." ixy="0." ixz="0." iyy="0." iyz="0." izz="0."/>
    </inertial>
    <visual>
      <origin xyz="-0. 0. -0." rpy="-0.0000001 -1.5707963 0. "/>
      <geometry>
        <mesh filename="meshes/hand1_link_3_3_visuals.obj" scale="1. 1. 1."/>
      </geometry>
    </visual>
    <collision>
      <origin xyz="-0. 0. -0." rpy="-0.0000001 -1.5707963 0. "/>
      <geometry>
        <mesh filename="meshes/hand1_link_3_3_collisions.obj" scale="1. 1. 1."/>
      </geometry>
    </collision>
  </link>
  <link name="hand1_link_4_1">
    <inertial>
      <origin xyz="0. 0. 0." rpy="0. 0. 0."/>
      <mass value="0.0059375"/>
      <inertia ixx="0." ixy="0." ixz="0." iyy="0." iyz="0." izz="0."/>
    </inertial>
    <visual>
      <origin xyz="0. 0. 0." rpy="0. -0. 0.0000001"/>
      <geometry>
        <mesh filename="meshes/hand1_link_4_1_visuals.obj" scale="1. 1. 1."/>
      </geometry>
    </visual>
    <collision>
      <origin xyz="0. 0. 0." rpy="0. -0. 0.0000001"/>
      <geometry>
        <mesh filename="meshes/hand1_link_4_1_collisions.obj" scale="1. 1. 1."/>
      </geometry>
    </collision>
  </link>
  <link name="hand1_link_4_2">
    <inertial>
      <origin xyz="0. 0. 0." rpy="0. 0. 0."/>
      <mass value="0.012005"/>
      <inertia ixx="0." ixy="0." ixz="0." iyy="0." iyz="0." izz="0."/>
    </inertial>
    <visual>
      <origin xyz="-0. -0. 0." rpy="0. -0. 0.0000001"/>
      <geometry>
        <mesh filename="meshes/hand1_link_4_2_visuals.obj" scale="1. 1. 1."/>
      </geometry>
    </visual>
    <collision>
      <origin xyz="-0. -0. 0." rpy="0. -0. 0.0000001"/>
      <geometry>
        <mesh filename="meshes/hand1_link_4_2_collisions.obj" scale="1. 1. 1."/>
      </geometry>
    </collision>
  </link>
  <link name="hand1_link_4_3">
    <inertial>
      <origin xyz="0. 0. 0." rpy="0. 0. 0."/>
      <mass value="0.0000002"/>
      <inertia ixx="0." ixy="0." ixz="0." iyy="0." iyz="0." izz="0."/>
    </inertial>
    <visual>
      <origin xyz="0. 0. -0." rpy="-0.0000001 -1.5707963 0. "/>
      <geometry>
        <mesh filename="meshes/hand1_link_4_3_visuals.obj" scale="1. 1. 1."/>
      </geometry>
    </visual>
    <collision>
      <origin xyz="0. 0. -0." rpy="-0.0000001 -1.5707963 0. "/>
      <geometry>
        <mesh filename="meshes/hand1_link_4_3_collisions.obj" scale="1. 1. 1."/>
      </geometry>
    </collision>
  </link>
  <link name="hand1_link_5_1">
    <inertial>
      <origin xyz="0. 0. 0." rpy="0. 0. 0."/>
      <mass value="0.0067858"/>
      <inertia ixx="0." ixy="0." ixz="0." iyy="0." iyz="0." izz="0."/>
    </inertial>
    <visual>
      <origin xyz="0. 0. 0." rpy="0. -0. 0."/>
      <geometry>
        <mesh filename="meshes/hand1_link_5_1_visuals.obj" scale="1. 1. 1."/>
      </geometry>
    </visual>
    <collision>
      <origin xyz="0. 0. 0." rpy="0. -0. 0."/>
      <geometry>
        <mesh filename="meshes/hand1_link_5_1_collisions.obj" scale="1. 1. 1."/>
      </geometry>
    </collision>
  </link>
  <link name="hand1_link_5_2">
    <inertial>
      <origin xyz="0. 0. 0." rpy="0. 0. 0."/>
      <mass value="0.0071121"/>
      <inertia ixx="0." ixy="0." ixz="0." iyy="0." iyz="0." izz="0."/>
    </inertial>
    <visual>
      <origin xyz="0. 0. 0." rpy="0. -0. 0."/>
      <geometry>
        <mesh filename="meshes/hand1_link_5_2_visuals.obj" scale="1. 1. 1."/>
      </geometry>
    </visual>
    <collision>
      <origin xyz="0. 0. 0." rpy="0. -0. 0."/>
      <geometry>
        <mesh filename="meshes/hand1_link_5_2_collisions.obj" scale="1. 1. 1."/>
      </geometry>
    </collision>
  </link>
  <link name="hand1_link_5_3">
    <inertial>
      <origin xyz="0. 0. 0." rpy="0. 0. 0."/>
      <mass value="0.0000002"/>
      <inertia ixx="0." ixy="0." ixz="0." iyy="0." iyz="0." izz="0."/>
    </inertial>
    <visual>
      <origin xyz="-0. 0. 0." rpy="-0. -1.5707963 0. "/>
      <geometry>
        <mesh filename="meshes/hand1_link_5_3_visuals.obj" scale="1. 1. 1."/>
      </geometry>
    </visual>
    <collision>
      <origin xyz="-0. 0. 0." rpy="-0. -1.5707963 0. "/>
      <geometry>
        <mesh filename="meshes/hand1_link_5_3_collisions.obj" scale="1. 1. 1."/>
      </geometry>
    </collision>
  </link>
  <link name="hand1_link_base">
    <inertial>
      <origin xyz="0. 0. 0." rpy="0. 0. 0."/>
      <mass value="0.22607"/>
      <inertia ixx="0." ixy="0." ixz="0." iyy="0." iyz="0." izz="0."/>
    </inertial>
    <visual>
      <origin xyz="0. 0. 0." rpy="0. 0. 0."/>
      <geometry>
        <mesh filename="meshes/hand1_link_base_visuals.obj" scale="1. 1. 1."/>
      </geometry>
    </visual>
    <collision>
      <origin xyz="0. 0. 0." rpy="0. 0. 0."/>
      <geometry>
        <mesh filename="meshes/hand1_link_base_collisions.obj" scale="1. 1. 1."/>
      </geometry>
    </collision>
  </link>
</robot>
